{
 "cells": [
  {
   "cell_type": "code",
   "execution_count": 9,
   "metadata": {},
   "outputs": [],
   "source": [
    "import tensorflow as tf\n",
    "from sklearn.preprocessing import StandardScaler\n",
    "import pandas as pd\n",
    "import os\n",
    "os.environ[\"TF_CPP_MIN_LOG_LEVEL\"] = \"2\"\n",
    "from sklearn.model_selection import train_test_split"
   ]
  },
  {
   "cell_type": "code",
   "execution_count": 10,
   "metadata": {},
   "outputs": [],
   "source": [
    "loaded_model = tf.keras.models.load_model('my_model')\n"
   ]
  },
  {
   "cell_type": "code",
   "execution_count": 11,
   "metadata": {},
   "outputs": [],
   "source": [
    "df = pd.read_csv('DATA/data_R_FCST.csv', header=0)"
   ]
  },
  {
   "cell_type": "code",
   "execution_count": 12,
   "metadata": {},
   "outputs": [],
   "source": [
    "X = df[['b (mm)','h (mm)','t (mm)','L (mm)','fy (MPa)','fc (MPa)']]\n",
    "y = df['N Test (kN)']"
   ]
  },
  {
   "cell_type": "code",
   "execution_count": 13,
   "metadata": {},
   "outputs": [],
   "source": [
    "scaler = StandardScaler()\n",
    "X = scaler.fit_transform(X)"
   ]
  },
  {
   "cell_type": "code",
   "execution_count": 14,
   "metadata": {},
   "outputs": [],
   "source": [
    "X_train, X_test, y_train, y_test = train_test_split(X, y, test_size=0.1,random_state=20)"
   ]
  },
  {
   "cell_type": "markdown",
   "metadata": {},
   "source": [
    "evaluate and status for testing data"
   ]
  },
  {
   "cell_type": "code",
   "execution_count": 15,
   "metadata": {},
   "outputs": [],
   "source": [
    "# loaded_model.evaluate(X_test, y_test)"
   ]
  },
  {
   "cell_type": "code",
   "execution_count": 16,
   "metadata": {},
   "outputs": [
    {
     "name": "stderr",
     "output_type": "stream",
     "text": [
      "2023-11-15 18:29:14.657533: E tensorflow/compiler/xla/stream_executor/cuda/cuda_blas.cc:188] failed to create cublas handle: the library was not initialized\n",
      "2023-11-15 18:29:14.657553: E tensorflow/compiler/xla/stream_executor/cuda/cuda_blas.cc:191] Failure to initialize cublas may be due to OOM (cublas needs some free memory when you initialize it, and your deep-learning framework may have preallocated more than its fair share), or may be because this binary was not built with support for the GPU in your machine.\n",
      "2023-11-15 18:29:14.657562: W tensorflow/core/framework/op_kernel.cc:1839] OP_REQUIRES failed at matmul_op_impl.h:804 : INTERNAL: Attempting to perform BLAS operation using StreamExecutor without BLAS support\n"
     ]
    },
    {
     "ename": "InternalError",
     "evalue": "Graph execution error:\n\nDetected at node sequential_1/dense_3/MatMul defined at (most recent call last):\n  File \"/usr/lib/python3.10/runpy.py\", line 196, in _run_module_as_main\n\n  File \"/usr/lib/python3.10/runpy.py\", line 86, in _run_code\n\n  File \"/home/max/.local/lib/python3.10/site-packages/ipykernel_launcher.py\", line 17, in <module>\n\n  File \"/home/max/.local/lib/python3.10/site-packages/traitlets/config/application.py\", line 1053, in launch_instance\n\n  File \"/home/max/.local/lib/python3.10/site-packages/ipykernel/kernelapp.py\", line 737, in start\n\n  File \"/home/max/.local/lib/python3.10/site-packages/tornado/platform/asyncio.py\", line 195, in start\n\n  File \"/usr/lib/python3.10/asyncio/base_events.py\", line 603, in run_forever\n\n  File \"/usr/lib/python3.10/asyncio/base_events.py\", line 1909, in _run_once\n\n  File \"/usr/lib/python3.10/asyncio/events.py\", line 80, in _run\n\n  File \"/home/max/.local/lib/python3.10/site-packages/ipykernel/kernelbase.py\", line 524, in dispatch_queue\n\n  File \"/home/max/.local/lib/python3.10/site-packages/ipykernel/kernelbase.py\", line 513, in process_one\n\n  File \"/home/max/.local/lib/python3.10/site-packages/ipykernel/kernelbase.py\", line 418, in dispatch_shell\n\n  File \"/home/max/.local/lib/python3.10/site-packages/ipykernel/kernelbase.py\", line 758, in execute_request\n\n  File \"/home/max/.local/lib/python3.10/site-packages/ipykernel/ipkernel.py\", line 426, in do_execute\n\n  File \"/home/max/.local/lib/python3.10/site-packages/ipykernel/zmqshell.py\", line 549, in run_cell\n\n  File \"/home/max/.local/lib/python3.10/site-packages/IPython/core/interactiveshell.py\", line 3046, in run_cell\n\n  File \"/home/max/.local/lib/python3.10/site-packages/IPython/core/interactiveshell.py\", line 3101, in _run_cell\n\n  File \"/home/max/.local/lib/python3.10/site-packages/IPython/core/async_helpers.py\", line 129, in _pseudo_sync_runner\n\n  File \"/home/max/.local/lib/python3.10/site-packages/IPython/core/interactiveshell.py\", line 3306, in run_cell_async\n\n  File \"/home/max/.local/lib/python3.10/site-packages/IPython/core/interactiveshell.py\", line 3488, in run_ast_nodes\n\n  File \"/home/max/.local/lib/python3.10/site-packages/IPython/core/interactiveshell.py\", line 3548, in run_code\n\n  File \"/tmp/ipykernel_157188/3545278922.py\", line 1, in <module>\n\n  File \"/home/max/.local/lib/python3.10/site-packages/keras/src/utils/traceback_utils.py\", line 65, in error_handler\n\n  File \"/home/max/.local/lib/python3.10/site-packages/keras/src/engine/training.py\", line 2631, in predict\n\n  File \"/home/max/.local/lib/python3.10/site-packages/keras/src/engine/training.py\", line 2416, in predict_function\n\n  File \"/home/max/.local/lib/python3.10/site-packages/keras/src/engine/training.py\", line 2401, in step_function\n\n  File \"/home/max/.local/lib/python3.10/site-packages/keras/src/engine/training.py\", line 2389, in run_step\n\n  File \"/home/max/.local/lib/python3.10/site-packages/keras/src/engine/training.py\", line 2357, in predict_step\n\n  File \"/home/max/.local/lib/python3.10/site-packages/keras/src/utils/traceback_utils.py\", line 65, in error_handler\n\n  File \"/home/max/.local/lib/python3.10/site-packages/keras/src/engine/training.py\", line 589, in __call__\n\n  File \"/home/max/.local/lib/python3.10/site-packages/keras/src/utils/traceback_utils.py\", line 65, in error_handler\n\n  File \"/home/max/.local/lib/python3.10/site-packages/keras/src/engine/base_layer.py\", line 1149, in __call__\n\n  File \"/home/max/.local/lib/python3.10/site-packages/keras/src/utils/traceback_utils.py\", line 96, in error_handler\n\n  File \"/home/max/.local/lib/python3.10/site-packages/keras/src/engine/sequential.py\", line 398, in call\n\n  File \"/home/max/.local/lib/python3.10/site-packages/keras/src/engine/functional.py\", line 515, in call\n\n  File \"/home/max/.local/lib/python3.10/site-packages/keras/src/engine/functional.py\", line 672, in _run_internal_graph\n\n  File \"/home/max/.local/lib/python3.10/site-packages/keras/src/utils/traceback_utils.py\", line 65, in error_handler\n\n  File \"/home/max/.local/lib/python3.10/site-packages/keras/src/engine/base_layer.py\", line 1149, in __call__\n\n  File \"/home/max/.local/lib/python3.10/site-packages/keras/src/utils/traceback_utils.py\", line 96, in error_handler\n\n  File \"/home/max/.local/lib/python3.10/site-packages/keras/src/layers/core/dense.py\", line 241, in call\n\nAttempting to perform BLAS operation using StreamExecutor without BLAS support\n\t [[{{node sequential_1/dense_3/MatMul}}]] [Op:__inference_predict_function_1535]",
     "output_type": "error",
     "traceback": [
      "\u001b[0;31m---------------------------------------------------------------------------\u001b[0m",
      "\u001b[0;31mInternalError\u001b[0m                             Traceback (most recent call last)",
      "\u001b[1;32m/home/max/Desktop/project 0.1 old/Graduation_Project/load_and_test.ipynb Cell 10\u001b[0m line \u001b[0;36m1\n\u001b[0;32m----> <a href='vscode-notebook-cell:/home/max/Desktop/project%200.1%20old/Graduation_Project/load_and_test.ipynb#X11sZmlsZQ%3D%3D?line=0'>1</a>\u001b[0m y_pre \u001b[39m=\u001b[39m loaded_model\u001b[39m.\u001b[39;49mpredict(X_test)\n\u001b[1;32m      <a href='vscode-notebook-cell:/home/max/Desktop/project%200.1%20old/Graduation_Project/load_and_test.ipynb#X11sZmlsZQ%3D%3D?line=1'>2</a>\u001b[0m y_pre \u001b[39m=\u001b[39m [i[\u001b[39m0\u001b[39m] \u001b[39mfor\u001b[39;00m i \u001b[39min\u001b[39;00m y_pre]\n\u001b[1;32m      <a href='vscode-notebook-cell:/home/max/Desktop/project%200.1%20old/Graduation_Project/load_and_test.ipynb#X11sZmlsZQ%3D%3D?line=2'>3</a>\u001b[0m pd\u001b[39m.\u001b[39mDataFrame(y_pre)\u001b[39m.\u001b[39mto_csv(\u001b[39m'\u001b[39m\u001b[39mpredicts.cvs\u001b[39m\u001b[39m'\u001b[39m,index_label\u001b[39m=\u001b[39m\u001b[39mFalse\u001b[39;00m,index\u001b[39m=\u001b[39m\u001b[39mFalse\u001b[39;00m)\n",
      "File \u001b[0;32m~/.local/lib/python3.10/site-packages/keras/src/utils/traceback_utils.py:70\u001b[0m, in \u001b[0;36mfilter_traceback.<locals>.error_handler\u001b[0;34m(*args, **kwargs)\u001b[0m\n\u001b[1;32m     67\u001b[0m     filtered_tb \u001b[39m=\u001b[39m _process_traceback_frames(e\u001b[39m.\u001b[39m__traceback__)\n\u001b[1;32m     68\u001b[0m     \u001b[39m# To get the full stack trace, call:\u001b[39;00m\n\u001b[1;32m     69\u001b[0m     \u001b[39m# `tf.debugging.disable_traceback_filtering()`\u001b[39;00m\n\u001b[0;32m---> 70\u001b[0m     \u001b[39mraise\u001b[39;00m e\u001b[39m.\u001b[39mwith_traceback(filtered_tb) \u001b[39mfrom\u001b[39;00m \u001b[39mNone\u001b[39;00m\n\u001b[1;32m     71\u001b[0m \u001b[39mfinally\u001b[39;00m:\n\u001b[1;32m     72\u001b[0m     \u001b[39mdel\u001b[39;00m filtered_tb\n",
      "File \u001b[0;32m~/.local/lib/python3.10/site-packages/tensorflow/python/eager/execute.py:60\u001b[0m, in \u001b[0;36mquick_execute\u001b[0;34m(op_name, num_outputs, inputs, attrs, ctx, name)\u001b[0m\n\u001b[1;32m     53\u001b[0m   \u001b[39m# Convert any objects of type core_types.Tensor to Tensor.\u001b[39;00m\n\u001b[1;32m     54\u001b[0m   inputs \u001b[39m=\u001b[39m [\n\u001b[1;32m     55\u001b[0m       tensor_conversion_registry\u001b[39m.\u001b[39mconvert(t)\n\u001b[1;32m     56\u001b[0m       \u001b[39mif\u001b[39;00m \u001b[39misinstance\u001b[39m(t, core_types\u001b[39m.\u001b[39mTensor)\n\u001b[1;32m     57\u001b[0m       \u001b[39melse\u001b[39;00m t\n\u001b[1;32m     58\u001b[0m       \u001b[39mfor\u001b[39;00m t \u001b[39min\u001b[39;00m inputs\n\u001b[1;32m     59\u001b[0m   ]\n\u001b[0;32m---> 60\u001b[0m   tensors \u001b[39m=\u001b[39m pywrap_tfe\u001b[39m.\u001b[39mTFE_Py_Execute(ctx\u001b[39m.\u001b[39m_handle, device_name, op_name,\n\u001b[1;32m     61\u001b[0m                                       inputs, attrs, num_outputs)\n\u001b[1;32m     62\u001b[0m \u001b[39mexcept\u001b[39;00m core\u001b[39m.\u001b[39m_NotOkStatusException \u001b[39mas\u001b[39;00m e:\n\u001b[1;32m     63\u001b[0m   \u001b[39mif\u001b[39;00m name \u001b[39mis\u001b[39;00m \u001b[39mnot\u001b[39;00m \u001b[39mNone\u001b[39;00m:\n",
      "\u001b[0;31mInternalError\u001b[0m: Graph execution error:\n\nDetected at node sequential_1/dense_3/MatMul defined at (most recent call last):\n  File \"/usr/lib/python3.10/runpy.py\", line 196, in _run_module_as_main\n\n  File \"/usr/lib/python3.10/runpy.py\", line 86, in _run_code\n\n  File \"/home/max/.local/lib/python3.10/site-packages/ipykernel_launcher.py\", line 17, in <module>\n\n  File \"/home/max/.local/lib/python3.10/site-packages/traitlets/config/application.py\", line 1053, in launch_instance\n\n  File \"/home/max/.local/lib/python3.10/site-packages/ipykernel/kernelapp.py\", line 737, in start\n\n  File \"/home/max/.local/lib/python3.10/site-packages/tornado/platform/asyncio.py\", line 195, in start\n\n  File \"/usr/lib/python3.10/asyncio/base_events.py\", line 603, in run_forever\n\n  File \"/usr/lib/python3.10/asyncio/base_events.py\", line 1909, in _run_once\n\n  File \"/usr/lib/python3.10/asyncio/events.py\", line 80, in _run\n\n  File \"/home/max/.local/lib/python3.10/site-packages/ipykernel/kernelbase.py\", line 524, in dispatch_queue\n\n  File \"/home/max/.local/lib/python3.10/site-packages/ipykernel/kernelbase.py\", line 513, in process_one\n\n  File \"/home/max/.local/lib/python3.10/site-packages/ipykernel/kernelbase.py\", line 418, in dispatch_shell\n\n  File \"/home/max/.local/lib/python3.10/site-packages/ipykernel/kernelbase.py\", line 758, in execute_request\n\n  File \"/home/max/.local/lib/python3.10/site-packages/ipykernel/ipkernel.py\", line 426, in do_execute\n\n  File \"/home/max/.local/lib/python3.10/site-packages/ipykernel/zmqshell.py\", line 549, in run_cell\n\n  File \"/home/max/.local/lib/python3.10/site-packages/IPython/core/interactiveshell.py\", line 3046, in run_cell\n\n  File \"/home/max/.local/lib/python3.10/site-packages/IPython/core/interactiveshell.py\", line 3101, in _run_cell\n\n  File \"/home/max/.local/lib/python3.10/site-packages/IPython/core/async_helpers.py\", line 129, in _pseudo_sync_runner\n\n  File \"/home/max/.local/lib/python3.10/site-packages/IPython/core/interactiveshell.py\", line 3306, in run_cell_async\n\n  File \"/home/max/.local/lib/python3.10/site-packages/IPython/core/interactiveshell.py\", line 3488, in run_ast_nodes\n\n  File \"/home/max/.local/lib/python3.10/site-packages/IPython/core/interactiveshell.py\", line 3548, in run_code\n\n  File \"/tmp/ipykernel_157188/3545278922.py\", line 1, in <module>\n\n  File \"/home/max/.local/lib/python3.10/site-packages/keras/src/utils/traceback_utils.py\", line 65, in error_handler\n\n  File \"/home/max/.local/lib/python3.10/site-packages/keras/src/engine/training.py\", line 2631, in predict\n\n  File \"/home/max/.local/lib/python3.10/site-packages/keras/src/engine/training.py\", line 2416, in predict_function\n\n  File \"/home/max/.local/lib/python3.10/site-packages/keras/src/engine/training.py\", line 2401, in step_function\n\n  File \"/home/max/.local/lib/python3.10/site-packages/keras/src/engine/training.py\", line 2389, in run_step\n\n  File \"/home/max/.local/lib/python3.10/site-packages/keras/src/engine/training.py\", line 2357, in predict_step\n\n  File \"/home/max/.local/lib/python3.10/site-packages/keras/src/utils/traceback_utils.py\", line 65, in error_handler\n\n  File \"/home/max/.local/lib/python3.10/site-packages/keras/src/engine/training.py\", line 589, in __call__\n\n  File \"/home/max/.local/lib/python3.10/site-packages/keras/src/utils/traceback_utils.py\", line 65, in error_handler\n\n  File \"/home/max/.local/lib/python3.10/site-packages/keras/src/engine/base_layer.py\", line 1149, in __call__\n\n  File \"/home/max/.local/lib/python3.10/site-packages/keras/src/utils/traceback_utils.py\", line 96, in error_handler\n\n  File \"/home/max/.local/lib/python3.10/site-packages/keras/src/engine/sequential.py\", line 398, in call\n\n  File \"/home/max/.local/lib/python3.10/site-packages/keras/src/engine/functional.py\", line 515, in call\n\n  File \"/home/max/.local/lib/python3.10/site-packages/keras/src/engine/functional.py\", line 672, in _run_internal_graph\n\n  File \"/home/max/.local/lib/python3.10/site-packages/keras/src/utils/traceback_utils.py\", line 65, in error_handler\n\n  File \"/home/max/.local/lib/python3.10/site-packages/keras/src/engine/base_layer.py\", line 1149, in __call__\n\n  File \"/home/max/.local/lib/python3.10/site-packages/keras/src/utils/traceback_utils.py\", line 96, in error_handler\n\n  File \"/home/max/.local/lib/python3.10/site-packages/keras/src/layers/core/dense.py\", line 241, in call\n\nAttempting to perform BLAS operation using StreamExecutor without BLAS support\n\t [[{{node sequential_1/dense_3/MatMul}}]] [Op:__inference_predict_function_1535]"
     ]
    }
   ],
   "source": [
    "y_pre = loaded_model.predict(X_test)\n",
    "y_pre = [i[0] for i in y_pre]\n",
    "pd.DataFrame(y_pre).to_csv('predicts.cvs',index_label=False,index=False)\n",
    "error = (y_test - y_pre)/y_test *100\n",
    "error = error.abs().sort_values()\n",
    "error.to_csv('error.csv', index=False,index_label=False)\n",
    "error.describe()"
   ]
  },
  {
   "cell_type": "markdown",
   "metadata": {},
   "source": [
    "evaluate and status for testing All data"
   ]
  },
  {
   "cell_type": "code",
   "execution_count": null,
   "metadata": {},
   "outputs": [],
   "source": [
    "loaded_model.evaluate(X, y)"
   ]
  },
  {
   "cell_type": "code",
   "execution_count": null,
   "metadata": {},
   "outputs": [],
   "source": [
    "y_pre = loaded_model.predict(X)\n",
    "y_pre = [i[0] for i in y_pre]\n",
    "pd.DataFrame(y_pre).to_csv('predicts.cvs',index_label=False,index=False)\n",
    "error = (y - y_pre)/y *100\n",
    "error = error.abs().sort_values()\n",
    "error.to_csv('error.csv', index=False,index_label=False)\n",
    "error.describe()"
   ]
  }
 ],
 "metadata": {
  "kernelspec": {
   "display_name": "Python 3",
   "language": "python",
   "name": "python3"
  },
  "language_info": {
   "codemirror_mode": {
    "name": "ipython",
    "version": 3
   },
   "file_extension": ".py",
   "mimetype": "text/x-python",
   "name": "python",
   "nbconvert_exporter": "python",
   "pygments_lexer": "ipython3",
   "version": "3.10.12"
  }
 },
 "nbformat": 4,
 "nbformat_minor": 2
}
